<?xml version="1.0" encoding="UTF-8"?>
<robot name="Robot">
    <link name="abstract_chassis_link">
        <inertial>
            <origin rpy="0.00000000 0.00000000 0.00000000" xyz="0.00000000 0.00000000 0.00000000"/>
            <mass value="1.00000000"/>
            <inertia ixx="1.00000000" ixy="0.00000000" ixz="0.00000000" iyy="1.00000000" iyz="0.00000000" izz="1.00000000"/>
        </inertial>
    </link>
    <link name="base">
        <inertial>
            <mass value="0"/>
            <inertia ixx="0" ixy="0" ixz="0" iyy="0" iyz="0" izz="0"/>
        </inertial>
    </link>
    <link name="base_link_x">
        <inertial>
            <origin rpy="0.00000000 0.00000000 0.00000000" xyz="0.00000000 0.00000000 0.00000000"/>
            <mass value="1.00000000"/>
            <inertia ixx="1.00000000" ixy="0.00000000" ixz="0.00000000" iyy="1.00000000" iyz="0.00000000" izz="1.00000000"/>
        </inertial>
    </link>
    <link name="base_link_y">
        <inertial>
            <origin rpy="0.00000000 0.00000000 0.00000000" xyz="0.00000000 0.00000000 0.00000000"/>
            <mass value="1.00000000"/>
            <inertia ixx="1.00000000" ixy="0.00000000" ixz="0.00000000" iyy="1.00000000" iyz="0.00000000" izz="1.00000000"/>
        </inertial>
    </link>
    <link name="left_arm_base_link">
        <inertial>
            <origin rpy="0.00000000 0.00000000 0.00000000" xyz="-0.00056340  0.03893400  0.00000319"/>
            <mass value="1.65800000"/>
            <inertia ixx="0.00105970" ixy="0.00001982" ixz="-0.00000017" iyy="0.00117870" iyz="-0.00000019" izz="0.00106470"/>
        </inertial>
    </link>
    <link name="left_arm_link1">
        <inertial>
            <origin rpy="0.00000000 0.00000000 0.00000000" xyz="0.00001500  0.10525900 -0.00195400"/>
            <mass value="1.16400000"/>
            <inertia ixx="0.00112500" ixy="0.00000000" ixz="0.00000000" iyy="0.00108400" iyz="-0.00002300" izz="0.00115800"/>
        </inertial>
    </link>
    <link name="left_arm_link2">
        <inertial>
            <origin rpy="0.00000000 0.00000000 0.00000000" xyz="-0.23622000  0.01635200 -0.00013275"/>
            <mass value="1.30000000"/>
            <inertia ixx="0.00060638" ixy="0.00041817" ixz="0.00014956" iyy="0.00759360" iyz="-0.00000809" izz="0.00757120"/>
        </inertial>
    </link>
    <link name="left_arm_link3">
        <inertial>
            <origin rpy="0.00000000 0.00000000 0.00000000" xyz="0.04511400  0.05461600 -0.00045593"/>
            <mass value="0.81800000"/>
            <inertia ixx="0.00060107" ixy="-0.00022467" ixz="-0.00000712" iyy="0.00139590" iyz="-0.00000975" izz="0.00150270"/>
        </inertial>
    </link>
    <link name="left_arm_link4">
        <inertial>
            <origin rpy="0.00000000 0.00000000 0.00000000" xyz="0.24285000 0.00237840 0.00000128"/>
            <mass value="0.69800000"/>
            <inertia ixx="0.00008450" ixy="-0.00000083" ixz="-0.00000000" iyy="0.00010174" iyz="0.00000001" izz="0.00009704"/>
        </inertial>
    </link>
    <link name="left_arm_link5">
        <inertial>
            <origin rpy="0.00000000 0.00000000 0.00000000" xyz="0.05430900 0.00418110 0.00000407"/>
            <mass value="0.41700000"/>
            <inertia ixx="0.00008400" ixy="0.00001623" ixz="0.00000007" iyy="0.00009850" iyz="-0.00000001" izz="0.00011333"/>
        </inertial>
    </link>
    <link name="left_arm_link6">
        <inertial>
            <origin rpy="0.00000000 0.00000000 0.00000000" xyz="0.02813800 0.00000012 0.00000005"/>
            <mass value="0.03700000"/>
            <inertia ixx="0.00000357" ixy="0.00000000" ixz="0.00000000" iyy="0.00000202" iyz="-0.00000000" izz="0.00000202"/>
        </inertial>
    </link>
    <link name="left_gripper_link">
        <inertial>
            <origin rpy="0.00000000 0.00000000 0.00000000" xyz="-0.03110700 -0.00000014 -0.00000014"/>
            <mass value="0.60400000"/>
            <inertia ixx="0.00017588" ixy="0.00000000" ixz="-0.00000000" iyy="0.00009864" iyz="-0.00000008" izz="0.00016512"/>
        </inertial>
    </link>
    <joint name="arm_mount_joint" type="fixed">
        <parent link="abstract_chassis_link"/>
        <child link="left_arm_base_link"/>
        <origin rpy="0.00000000  0.00000000 -1.57080000" xyz="0.15995000 0.00000000 0.94650000"/>
        <axis xyz="100"/>
    </joint>
    <joint name="joint_theta" type="revolute">
        <parent link="base_link_y"/>
        <child link="abstract_chassis_link"/>
        <origin rpy="0.00000000 0.00000000 0.00000000" xyz="0.00000000 0.00000000 0.00000000"/>
        <axis xyz="0.00000000 0.00000000 1.00000000"/>
        <limit lower="-Inf" upper="Inf" effort="0" velocity="0"/>
    </joint>
    <joint name="joint_x" type="prismatic">
        <parent link="base"/>
        <child link="base_link_x"/>
        <origin rpy="0.00000000 0.00000000 0.00000000" xyz="0.00000000 0.00000000 0.00000000"/>
        <axis xyz="0.00000000 0.00000000 1.00000000"/>
        <limit lower="-50.00000000" upper="50.00000000" effort="0" velocity="0"/>
    </joint>
    <joint name="joint_y" type="prismatic">
        <parent link="base_link_x"/>
        <child link="base_link_y"/>
        <origin rpy="0.00000000 0.00000000 0.00000000" xyz="0.00000000 0.00000000 0.00000000"/>
        <axis xyz="0.00000000 1.00000000 0.00000000"/>
        <limit lower="-50.00000000" upper="50.00000000" effort="0" velocity="0"/>
    </joint>
    <joint name="left_arm_joint1" type="revolute">
        <parent link="left_arm_base_link"/>
        <child link="left_arm_link1"/>
        <origin rpy="0.00000000 0.00000000 0.00000000" xyz="-0.00111490  0.04460000  0.00000000"/>
        <axis xyz="0.00000000 1.00000000 0.00000000"/>
        <limit lower="-2.87980000" upper="2.87980000" effort="0" velocity="0"/>
    </joint>
    <joint name="left_arm_joint2" type="revolute">
        <parent link="left_arm_link1"/>
        <child link="left_arm_link2"/>
        <origin rpy="0.00000000 0.00000000 0.00000000" xyz="0.00000000 0.10610000 0.00000000"/>
        <axis xyz="0.00000000  0.00000000 -1.00000000"/>
        <limit lower="0.00000000" upper="3.22890000" effort="0" velocity="0"/>
    </joint>
    <joint name="left_arm_joint3" type="revolute">
        <parent link="left_arm_link2"/>
        <child link="left_arm_link3"/>
        <origin rpy="0.00000000 0.00000000 0.00000000" xyz="-0.34928000  0.01999800  0.00000000"/>
        <axis xyz="0.00000000  0.00000000 -1.00000000"/>
        <limit lower="-3.31610000" upper="0.00000000" effort="0" velocity="0"/>
    </joint>
    <joint name="left_arm_joint4" type="revolute">
        <parent link="left_arm_link3"/>
        <child link="left_arm_link4"/>
        <origin rpy="0.00000000 0.00000000 0.00000000" xyz="0.02735000 0.06976700 0.00000000"/>
        <axis xyz="1.00000000 0.00000000 0.00000000"/>
        <limit lower="-2.87980000" upper="2.87980000" effort="0" velocity="0"/>
    </joint>
    <joint name="left_arm_joint5" type="revolute">
        <parent link="left_arm_link4"/>
        <child link="left_arm_link5"/>
        <origin rpy="0.00000000 0.00000000 0.00000000" xyz="0.24630000 -0.00049894  0.00000000"/>
        <axis xyz="0.00000000 1.00000000 0.00000000"/>
        <limit lower="-1.65810000" upper="1.65810000" effort="0" velocity="0"/>
    </joint>
    <joint name="left_arm_joint6" type="revolute">
        <parent link="left_arm_link5"/>
        <child link="left_arm_link6"/>
        <origin rpy="0.00000000 0.00000000 0.00000000" xyz="0.05824900 0.00050025 0.00000000"/>
        <axis xyz="1.00000000 0.00000000 0.00000000"/>
        <limit lower="-2.87980000" upper="2.87980000" effort="0" velocity="0"/>
    </joint>
    <joint name="left_gripper_joint" type="fixed">
        <parent link="left_arm_link6"/>
        <child link="left_gripper_link"/>
        <origin rpy="0.00000000 0.00000000 0.00000000" xyz="0.10390000 0.00000000 0.00000000"/>
        <axis xyz="100"/>
    </joint>
</robot>
